Workbook

Sheet JARDINS FAMILIAUX
A1: FID | B1: NOM | C1: DATE | D1: SURPERFICIE M2
A2: 1 | B2: Kleingärten | C2: 2026 | D2: 25400.674
A3: 2 | B3: LES CEDRES | C3: 2026 | D3: 8735.6731
A4: 3 | B4: KLEINGARTENANLAGE | C4: 2026 | D4: 3837.7633 | F4: TOTAL | G4: =SUM(Tableau2[SURPERFICIE M2]) -> 2227302.8
A5: 4 | B5: CITÉ WESTHOFFEN | C5: 2026 | D5: 10199.179
A6: 5 | B6: JARDINS FAMILIAUX DE LA VOGELAU 2 | C6: 2026 | D6: 8043.4403
A7: 6 | C7: 2026 | D7: 6153.4257
A8: 7 | B8: JARDINS | C8: 2026 | D8: 3461.6039
A9: 8 | B9: CIRIERS | C9: 2026 | D9: 3823.4797
A10: 9 | B10: KALTAU 1 | C10: 2026 | D10: 2279.8536
A11: 10 | B11: BREITLACH | C11: 2026 | D11: 67308.304
A12: 11 | B12: ELSAU | C12: 2026 | D12: 2762.4048
A13: 12 | B13: KALTAU 2 | C13: 2026 | D13: 5570.2213
A14: 13 | C14: 2026 | D14: 4629.1898
A15: 14 | B15: LOMBARTSWOERTH | C15: 2026 | D15: 1384.366
A16: 15 | B16: KURGARTEN | C16: 2026 | D16: 4784.8353
A17: 16 | B17: JARDINS FAMILIAUX | C17: 2026 | D17: 3762.4369
A18: 17 | C18: 2026 | D18: 56674.991
A19: 18 | B19: MUSAU | C19: 2026 | D19: 4979.3908
A20: 19 | B20: LABROQUE | C20: 2026 | D20: 2648.6871
A21: 20 | C21: 2026 | D21: 1015.2471
A22: 21 | C22: 2026 | D22: 2895.9019
A23: 22 | B23: JARDIN PARTAGE | C23: 2026 | D23: 1780.021
A24: 23 | C24: 2026 | D24: 5100.7187
A25: 24 | B25: PARC DE CRONENBOURG | C25: 2026 | D25: 5036.0598
A26: 25 | B26: JARDINS FAMILIAUX | C26: 2026 | D26: 9804.9668
A27: 26 | B27: JARDINS FAMILIAUX AU WIHREL | C27: 2026 | D27: 5129.9202
A28: 27 | C28: 2026 | D28: 1501.2598
A29: 28 | B29: MAQUIS | C29: 2026 | D29: 11008.1
A30: 29 | B30: WOLFSLOCH | C30: 2026 | D30: 7131.572
A31: 30 | B31: HEYRITZ | C31: 2026 | D31: 1662.1751
A32: 31 | B32: ELSAU | C32: 2026 | D32: 1451.7271
A33: 32 | B33: GRUNEBERGEBLEICHE | C33: 2026 | D33: 590.14974
A34: 33 | B34: KIBITZENAU | C34: 2026 | D34: 719.65431
A35: 34 | B35: GRUNEBERGEBLEICHE | C35: 2026 | D35: 1619.3291
A36: 35 | B36: KRUMMERORT | C36: 2026 | D36: 9417.4904
A37: 36 | B37: LOMBARTSWOERTH | C37: 2026 | D37: 2221.5744
A38: 37 | B38: WACKEN | C38: 2026 | D38: 16498.751
A39: 38 | B39: JONCS | C39: 2026 | D39: 4785.5165
A40: 39 | B40: KALTAU 1 | C40: 2026 | D40: 38327.409
...

Sheet JARDINS PARTAGES
A1: FID | B1: NOM | C1: DATE | D1: SUPERFICIE M2
A2: 1 | B2: JARDINS PARTAGES GENERAL UHRICH | C2: 2025 | D2: 346
A3: 2 | B3: JARDINS PARTAGES ROUE | C3: 2025 | D3: 2167
A4: 3 | B4: JARDINS PARTAGES ROETHIG | C4: 2025 | D4: 108
A5: 4 | B5: JARDINS PARTAGES GROSSAU | C5: 2025 | D5: 387
A6: 5 | B6: JARDINS PARTAGES BALLON | C6: 2025 | D6: 555
A7: 6 | B7: JARDINS PARTAGES BRIN DE PAILLE | C7: 2025 | D7: 16575
A8: 7 | B8: JARDINS PARTAGES ST-GALLE PERMACULTURE | C8: 2025 | D8: 7972
A9: 8 | B9: JARDINS PARTAGES RIFF | C9: 2025 | D9: 667
A10: 9 | B10: JARDINS PARTAGES JACQUELINE | C10: 2025 | D10: 907
A11: 10 | B11: JARDINS PARTAGES LENTILLES | C11: 2025 | D11: 89
A12: 11 | B12: JARDINS PARTAGES GF STRASS | C12: 2025 | D12: 707 | F12: TOTAL | G12: =SUM(D2:D56) -> 91066
A13: 12 | B13: JARDINS PARTAGES ALISIERS | C13: 2025 | D13: 585
A14: 13 | B14: JARDIN PARTAGE DU RACINE CLUB | C14: 2025 | D14: 1052
A15: 14 | B15: JARDINS PARTAGES APOLLONIA | C15: 2025 | D15: 3490
A16: 15 | B16: JARDINS PARTAGES DE KUPFERHAMMER | C16: 2025 | D16: 6833
A17: 16 | B17: JARDINS PARTAGES QUINTA FLORENTINA | C17: 2025 | D17: 3293
A18: 17 | B18: JARDINS PARTAGES LOMBRIC HARDI | C18: 2025 | D18: 1499
A19: 18 | B19: JARDINS PARTAGES KARINE | D19: 573
A20: 19 | B20: JARDINS PARTAGES CATHERINE | D20: 856
A21: 20 | B21: JARDINS PARTAGES SOUS LE SOLEIL | D21: 399
A22: 21 | B22: JARDINS PARTAGES CSC L'ESCALE | D22: 622
A23: 22 | B23: JARDINS POTTIER / RENAISSANCE | D23: 432
A24: 23 | B24: JARDINS PARTAGES JACOUTOT | D24: 2335
A25: 24 | B25: JARDINS PARTAGES MELANIE | D25: 5973
A26: 25 | B26: JARDINS PARTAGES FRIDOLIN | D26: 969
A27: 26 | B27: JARDINS PARTAGES LE CHOU DE BRUXELLES | D27: 686
A28: 27 | B28: JARDINS PARTAGES SQUARE ST-JEAN | D28: 159
A29: 28 | B29: JARDINS PARTAGES DU JEU DE PAUME | D29: 19
A30: 29 | B30: JARDINS PARTAGES L'ARROSOIR | D30: 378
... A56: 55 | B56: FORET NOURRICIERE PARTAGEE DES PLANTEURS CUEILLEURS | D56: 6242

Sheet JARDINS PRODUCTIFS
A1: FID | B1: NOM | C1: DATE | D1: SUPERFICIE M2
A2: 1 | B2: APOLLINE | C2: 2025 | D2: 24.3
A3: 2 | B3: CELINE&BEN | C3: 2025 | D3: 38 | E3: total | F3: =SUM(D2:D5) -> 4860.3
A4: 3 | B4: DOMINIQUE | C4: 2025 | D4: 305
A5: 4 | B5: FERME DU HOHBERG | C5: 2025 | D5: 4493
A6: 5 | B6: JARDIN FRIDOLIN | C6: 2025 | D6: 969
A7: 6 | B7: LANDSBERG | C7: 2025 | D7: 647
A8: 7 | B8: LE CHOU DE BRUXELLES | C8: 2025 | D8: 686
A9: 8 | B9: LE LOMBRIC HARDI | C9: 2025 | D9: 1424
A10: 9 | B10: MASSIF NOURRICIER ESPLANADE | C10: 2025 | D10: 289
A11: 10 | B11: RAPHAEL | C11: 2025 | D11: NA
G21: JARDINs DÉJÀ PRIT EN COMPTE DANS LEUR CATE RESPECTIFS

Sheet PUC
A1: FID | B1: NOM | C1: DATE | D1: SUPERFICIE M2
A2: 1 | B2: PUC GUYNEMER | C2: 2025 | D2: 9734
A3: 2 | B3: PUC ST-GALL | C3: 2025 | D3: 1881 | F3: total | G3: =SUM(D2:D6) -> 14196
A4: 3 | B4: PUC ELSAU | C4: 2025 | D4: 714
A5: 5 | B5: PUC CITADELLE | C5: 2025 | D5: 1173
A6: 6 | B6: PUC FOULONS | C6: 2025 | D6: 694

Sheet CITES FERTILLES
A13: FID | B13: NOM | C13: DATE | D13: SUPERFICIE M2
A14: 1 | B14: CITE FERTILE ILL DES TERRES NOUVELLES | C14: 2026 | D14: 9300
A15: 2 | B15: VERGER DES POIRES SECOUEES | C15: 2026 | D15: 8085 | E15: TOTAL | F15: =SUM(D14:D15) -> 17385

Sheet MASSIFS NOURRICIERS
A1: FID | B1: NOM | C1: DATE | D1: SUPERFICIE M2
A2: 1 | B2: Massif nourricier Esplanade | C2: 2026 | D2: 289
A3: 2 | B3: Massif nourricier Gare | C3: 2026 | D3: 641
E5: TOTAL | F5: =SUM(D2,D3) -> 930

Sheet TOTAL_SUPERFICIE
A1: Jardins répertoriés | B1: SUPERFICIE
A2: FAMILIAUX | B2: =('JARDINS FAMILIAUX'!G4) -> 2227302.8
A3: PARTAGES | B3: ='JARDINS PARTAGES'!G12 -> 91066
A4: PRODUCTIFS | B4: 8892.3
A5: PUC | B5: =(PUC!G3) -> 14196
A6: CITES FERTILES | B6: ='CITES FERTILLES'!F15 -> 17385
A7: MASSIFS NOURRICIERS | B7: ='MASSIFS NOURRICIERS'!F5 -> 930
A10: TOTAL des jardins m2 | B10: =SUM(B2:B7) -> 2359772.1
A11: HECTARES | B11: =B10/10000 -> 235.97721
A13: SUPERFICIE Eurométropole Strasbourg km2 | B13: 337.6
A14: SUPERFICIE Eurométropole Strasbourg ha | B14: =B13*100 -> 33760
A15: SUPERFICIE Strasbourg ha | B15: 7829.4
A17: Pourcentage de jardin au sein de l'EMS | B17: =B11/B14 -> 0.0069898462
A18: Pourcentage de jardin au sein de Strasbourg | B18: =B11/B15 -> 0.030139884

Sheet NOMBRE
A1: JARDINS REPERTORIES | B1: NOMBRE
A2: FAMILIAUX | B2: =COUNT('JARDINS FAMILIAUX'!A:A) -> 215
A3: PARTAGES | B3: =COUNTA('JARDINS PARTAGES'!B2:B56) -> 55
A4: PRODUCTIFS | B4: =COUNTA('JARDINS PRODUCTIFS'!B2:B5,'JARDINS PRODUCTIFS'!B11:B11) -> 5
A5: PUC | B5: =COUNTA(PUC!B2:B6) -> 5
A6: CITES FERTILES | B6: =COUNTA('CITES FERTILLES'!B14:B15) -> 2
A7: MASSIFS NOURRICIERS | B7: =COUNTA('MASSIFS NOURRICIERS'!B2:B3) -> 2
A10: TOTAL | B10: =SUM(B2:B7) -> 284
